<?xml version="1.0"?>
<robot xmlns:xacro="http://ros.org/wiki/xacro" name="omni_amr">
    <xacro:include filename="$(find amr_simulation)/robots/omni_type/xacros/omni_amr.specs"/>
    
    <xacro:macro name="fixed_wheel_left" params="name parent">
    
    <!-- <joint name="${name}_joint" type="revolute"> -->
    <joint name="${name}_joint" type="continuous">
        <origin xyz="0 0 -0.065" rpy="0 0 0"/>
        <!-- <limit effort="1000.0" lower="-1e+16" upper="1e+16" velocity="3.5"/> -->
        <!-- <joint_properties damping="1.0" friction="1" /> -->
        <parent link="${parent}" />
        <child link="${name}_link" />
        <axis xyz="0 1 0" />
    </joint>

    <link name="${name}_link">
        <inertial>
            <mass value="${wheel_mass}"/>
            <origin xyz="0 0 0" rpy="0 1.5707 1.5707"/>
            <inertia ixx="${wheel_mass * (1.0/12.0 * wheel_wid_sq + 0.25 * wheel_rad_sq)}"
                    iyy="${wheel_mass * (1.0/12.0 * wheel_wid_sq + 0.25 * wheel_rad_sq)}"
                    izz="${0.5 * wheel_mass * wheel_rad_sq}"
                    ixy="0.0" ixz="0.0" iyz="0.0"/>
        </inertial>

        <collision>
            <origin xyz="0 0 0" rpy="0 1.5707 1.5707"/>
            <geometry>
                <cylinder radius="${wheel_rad}" length="${wheel_wid}"/>
            </geometry>
        </collision>

        <visual>
            <origin xyz="0 0 0" rpy="0 1.5707 1.5707"/>
            <geometry>
                <cylinder radius="${wheel_rad}" length="${wheel_wid}"/>
            </geometry>
        </visual>
    </link>

    <gazebo reference="${name}_link">
        <!-- <kp>100000.0</kp> 
        <kd>50.0</kd> -->
        <mu1>10.0</mu1>
        <mu2>1.0</mu2>
    </gazebo>

    </xacro:macro>

</robot>

